<?xml version="1.0" ?>
<!-- =================================================================================== -->
<!-- |    This document was autogenerated by xacro from h1_robot.urdf.xacro            | -->
<!-- |    EDITING THIS FILE BY HAND IS NOT RECOMMENDED                                 | -->
<!-- =================================================================================== -->
<robot name="h1_robot">
  <link name="fake_link">
    <visual>
      <origin rpy="0 0 0" xyz="0 0 0"/>
      <geometry>
        <box size="0.001 0.001 0.001"/>
      </geometry>
    </visual>
  </link>
  <joint name="fake_joint" type="fixed">
    <origin rpy="0 0 0" xyz="0 0 0.001"/>
    <parent link="fake_link"/>
    <child link="base_link"/>
  </joint>
  <link name="base_link">
    <inertial>
      <origin rpy="0 0 0" xyz="0.000740033557061207 -2.89813835710668E-09 -0.238489145485207"/>
      <mass value="1.49428013879955"/>
      <inertia ixx="0.00364768535837031" ixy="-6.32316601308359E-12" ixz="1.99592617911289E-05" iyy="0.00358098929975865" iyz="1.694588043219E-10" izz="0.00589788150834425"/>
    </inertial>
    <visual>
      <!-- <origin
        xyz="0 0 0"
        rpy="0 0 0" /> -->
      <origin rpy="0 0 0" xyz="0 0 0.2605"/>
      <geometry>
        <mesh filename="file:///home/robotck/ros2_ws/install/h1_description/share/h1_description/meshes/visual/base_link.STL"/>
      </geometry>
      <material name="">
        <color rgba="0.792156862745098 0.819607843137255 0.933333333333333 1"/>
      </material>
    </visual>
    <collision>
      <!-- <origin
        xyz="0 0 0"
        rpy="0 0 0" /> -->
      <origin rpy="0 0 0" xyz="0 0 0.2605"/>
      <geometry>
        <mesh filename="file:///home/robotck/ros2_ws/install/h1_description/share/h1_description/meshes/visual/base_link.STL"/>
      </geometry>
    </collision>
  </link>
  <link name="link-J1">
    <inertial>
      <origin rpy="0 0 0" xyz="-3.57404692468406E-06 0.000688736209329804 -0.048157767674012"/>
      <mass value="2.54080545346503"/>
      <inertia ixx="0.0132749391170704" ixy="2.31449133162819E-07" ixz="-2.13862912949809E-07" iyy="0.0125700390893002" iyz="0.000459806363175522" izz="0.00481564822894174"/>
    </inertial>
    <visual>
      <origin rpy="0 0 0" xyz="0 0 0"/>
      <geometry>
        <mesh filename="file:///home/robotck/ros2_ws/install/h1_description/share/h1_description/meshes/visual/link-J1.STL"/>
      </geometry>
      <material name="">
        <color rgba="0.792156862745098 0.819607843137255 0.933333333333333 1"/>
      </material>
    </visual>
    <collision>
      <origin rpy="0 0 0" xyz="0 0 0"/>
      <geometry>
        <mesh filename="file:///home/robotck/ros2_ws/install/h1_description/share/h1_description/meshes/visual/link-J1.STL"/>
      </geometry>
    </collision>
  </link>
  <joint name="J1" type="revolute">
    <!-- <origin
      xyz="0 0 0"
      rpy="0 0 0" /> -->
    <origin rpy="0 0 0" xyz="0 0 0.2605"/>
    <parent link="base_link"/>
    <child link="link-J1"/>
    <axis xyz="0 0 -1"/>
    <limit effort="0" lower="-3.0543" upper="3.0543" velocity="0"/>
  </joint>
  <link name="link-Body">
    <inertial>
      <origin rpy="0 0 0" xyz="0.00246787748091909 0.249525517413171 0.000596924634415743"/>
      <mass value="3.3194687242283"/>
      <inertia ixx="0.0418183673295349" ixy="0.000751091538850231" ixz="2.15290683247481E-07" iyy="0.0233117881051513" iyz="-1.23200531111601E-05" izz="0.0309354173276001"/>
    </inertial>
    <visual>
      <origin rpy="0 0 0" xyz="0 0 0"/>
      <geometry>
        <mesh filename="file:///home/robotck/ros2_ws/install/h1_description/share/h1_description/meshes/visual/link-Body.STL"/>
      </geometry>
      <material name="">
        <color rgba="0.792156862745098 0.819607843137255 0.933333333333333 1"/>
      </material>
    </visual>
    <collision>
      <origin rpy="0 0 0" xyz="0 0 0"/>
      <geometry>
        <mesh filename="file:///home/robotck/ros2_ws/install/h1_description/share/h1_description/meshes/visual/link-Body.STL"/>
      </geometry>
    </collision>
  </link>
  <joint name="Body" type="revolute">
    <origin rpy="1.5708 0 0" xyz="0 0  0"/>
    <parent link="link-J1"/>
    <child link="link-Body"/>
    <axis xyz="0 0 1"/>
    <limit effort="0" lower="-1" upper="1" velocity="0"/>
  </joint>
  <link name="link-R0">
    <inertial>
      <origin rpy="0 0 0" xyz="-5.36064345635264E-06 -0.000550017814507475 0.0379327952026104"/>
      <mass value="3.46085446917408"/>
      <inertia ixx="0.00462413861199453" ixy="1.10874369896872E-06" ixz="-5.2405532829301E-06" iyy="0.00500474262753878" iyz="-4.74046783101803E-05" izz="0.00508731121895653"/>
    </inertial>
    <visual>
      <origin rpy="0 0 0" xyz="0 0 0"/>
      <geometry>
        <mesh filename="file:///home/robotck/ros2_ws/install/h1_description/share/h1_description/meshes/visual/link-R0.STL"/>
      </geometry>
      <material name="">
        <color rgba="0.776470588235294 0.756862745098039 0.737254901960784 1"/>
      </material>
    </visual>
    <collision>
      <origin rpy="0 0 0" xyz="0 0 0"/>
      <geometry>
        <mesh filename="file:///home/robotck/ros2_ws/install/h1_description/share/h1_description/meshes/visual/link-R0.STL"/>
      </geometry>
    </collision>
  </link>
  <joint name="R-J0" type="fixed">
    <origin rpy="0 0 0" xyz="0 0.38 0.075"/>
    <parent link="link-Body"/>
    <child link="link-R0"/>
    <axis xyz="0 0 0"/>
    <limit effort="0" lower="0" upper="0" velocity="0"/>
  </joint>
  <link name="link-R1">
    <inertial>
      <origin rpy="0 0 0" xyz="-0.00391495384324204 3.44953460352793E-05 -0.0356925083781218"/>
      <mass value="3.84687374351761"/>
      <inertia ixx="0.00397927734142592" ixy="1.32956171092165E-06" ixz="-2.11559425234039E-06" iyy="0.0032661789850321" iyz="1.14620036600572E-06" izz="0.00266637011175435"/>
    </inertial>
    <visual>
      <origin rpy="0 0 0" xyz="0 0 0"/>
      <geometry>
        <mesh filename="file:///home/robotck/ros2_ws/install/h1_description/share/h1_description/meshes/visual/link-R1.STL"/>
      </geometry>
      <material name="">
        <color rgba="0.776470588235294 0.756862745098039 0.737254901960784 1"/>
      </material>
    </visual>
    <collision>
      <origin rpy="0 0 0" xyz="0 0 0"/>
      <geometry>
        <mesh filename="file:///home/robotck/ros2_ws/install/h1_description/share/h1_description/meshes/visual/link-R1.STL"/>
      </geometry>
    </collision>
  </link>
  <joint name="R-J1" type="revolute">
    <origin rpy="0 0 0" xyz="0 0 0.172"/>
    <parent link="link-R0"/>
    <child link="link-R1"/>
    <axis xyz="0 0 1"/>
    <limit effort="0" lower="-3.0543" upper="3.0543" velocity="0"/>
  </joint>
  <link name="link-R2">
    <inertial>
      <origin rpy="0 0 0" xyz="3.86490177528565E-07 -0.0452420553770264 0.0066905148073625"/>
      <mass value="4.59473657520835"/>
      <inertia ixx="0.0149236633858357" ixy="4.66017394464824E-06" ixz="6.67787071273893E-07" iyy="0.00622043748645023" iyz="-0.00157051411608724" izz="0.0130507506497026"/>
    </inertial>
    <visual>
      <origin rpy="0 0 0" xyz="0 0 0"/>
      <geometry>
        <mesh filename="file:///home/robotck/ros2_ws/install/h1_description/share/h1_description/meshes/visual/link-R2.STL"/>
      </geometry>
      <material name="">
        <color rgba="0.776470588235294 0.756862745098039 0.737254901960784 1"/>
      </material>
    </visual>
    <collision>
      <origin rpy="0 0 0" xyz="0 0 0"/>
      <geometry>
        <mesh filename="file:///home/robotck/ros2_ws/install/h1_description/share/h1_description/meshes/visual/link-R2.STL"/>
      </geometry>
    </collision>
  </link>
  <joint name="R-J2" type="revolute">
    <origin rpy="-1.5708 0 -1.5708" xyz="0 0 0"/>
    <parent link="link-R1"/>
    <child link="link-R2"/>
    <axis xyz="0 0 1"/>
    <limit effort="0" lower="-1.6" upper="1.6" velocity="0"/>
  </joint>
  <link name="link-R3">
    <inertial>
      <origin rpy="0 0 0" xyz="0.00324047095926137 0.00110288578196249 -0.0819918016100478"/>
      <mass value="4.5854332927521"/>
      <inertia ixx="0.0115360168840183" ixy="4.15752513335911E-06" ixz="1.48969963687349E-05" iyy="0.0108939919528904" iyz="-0.000234057856310516" izz="0.00358981276852546"/>
    </inertial>
    <visual>
      <origin rpy="0 0 0" xyz="0 0 0"/>
      <geometry>
        <mesh filename="file:///home/robotck/ros2_ws/install/h1_description/share/h1_description/meshes/visual/link-R3.STL"/>
      </geometry>
      <material name="">
        <color rgba="0.776470588235294 0.756862745098039 0.737254901960784 1"/>
      </material>
    </visual>
    <collision>
      <origin rpy="0 0 0" xyz="0 0 0"/>
      <geometry>
        <mesh filename="file:///home/robotck/ros2_ws/install/h1_description/share/h1_description/meshes/visual/link-R3.STL"/>
      </geometry>
    </collision>
  </link>
  <joint name="R-J3" type="revolute">
    <origin rpy="1.5708 -1.5708 0" xyz="0 -0.3 0"/>
    <parent link="link-R2"/>
    <child link="link-R3"/>
    <axis xyz="0 0 1"/>
    <limit effort="0" lower="-3.0543" upper="3.0543" velocity="0"/>
  </joint>
  <link name="link-R4">
    <inertial>
      <origin rpy="0 0 0" xyz="3.18423349929819E-05 -0.0368779539653267 -0.0139387490180007"/>
      <mass value="3.87071086851708"/>
      <inertia ixx="0.0111305426375428" ixy="-2.98701447860813E-06" ixz="-4.85972985817775E-06" iyy="0.00460974095759748" iyz="0.00198988285390344" izz="0.00993670762454385"/>
    </inertial>
    <visual>
      <origin rpy="0 0 0" xyz="0 0 0"/>
      <geometry>
        <mesh filename="file:///home/robotck/ros2_ws/install/h1_description/share/h1_description/meshes/visual/link-R4.STL"/>
      </geometry>
      <material name="">
        <color rgba="0.776470588235294 0.756862745098039 0.737254901960784 1"/>
      </material>
    </visual>
    <collision>
      <origin rpy="0 0 0" xyz="0 0 0"/>
      <geometry>
        <mesh filename="file:///home/robotck/ros2_ws/install/h1_description/share/h1_description/meshes/visual/link-R4.STL"/>
      </geometry>
    </collision>
  </link>
  <joint name="R-J4" type="revolute">
    <origin rpy="-1.5708 0 -1.5708" xyz="0 0 0"/>
    <parent link="link-R3"/>
    <child link="link-R4"/>
    <axis xyz="0 0 1"/>
    <limit effort="0" lower="-1.7" upper="2.2" velocity="0"/>
  </joint>
  <link name="link-R5">
    <inertial>
      <origin rpy="0 0 0" xyz="0.00322215689066335 7.4948711252687E-05 -0.0572975679008713"/>
      <mass value="1.82124545231834"/>
      <inertia ixx="0.00278208630631441" ixy="7.08235437752721E-08" ixz="-4.67880502096544E-05" iyy="0.00248903276285" iyz="8.97378635589642E-07" izz="0.00124650141864315"/>
    </inertial>
    <visual>
      <origin rpy="0 0 0" xyz="0 0 0"/>
      <geometry>
        <mesh filename="file:///home/robotck/ros2_ws/install/h1_description/share/h1_description/meshes/visual/link-R5.STL"/>
      </geometry>
      <material name="">
        <color rgba="0.776470588235294 0.756862745098039 0.737254901960784 1"/>
      </material>
    </visual>
    <collision>
      <origin rpy="0 0 0" xyz="0 0 0"/>
      <geometry>
        <mesh filename="file:///home/robotck/ros2_ws/install/h1_description/share/h1_description/meshes/visual/link-R5.STL"/>
      </geometry>
    </collision>
  </link>
  <joint name="R-J5" type="revolute">
    <origin rpy="1.5708 -1.5708 0" xyz="0 -0.22 0"/>
    <parent link="link-R4"/>
    <child link="link-R5"/>
    <axis xyz="0 0 1"/>
    <limit effort="0" lower="-3.0543" upper="3.0543" velocity="0"/>
  </joint>
  <link name="link-R6">
    <inertial>
      <origin rpy="0 0 0" xyz="-9.36842091880941E-06 -0.0325947019861453 -0.0133468991574915"/>
      <mass value="2.86918680878616"/>
      <inertia ixx="0.00331600824470928" ixy="-5.37053937468114E-07" ixz="1.34740423005078E-06" iyy="0.00200841766148693" iyz="0.000558066732796783" izz="0.00366760091811977"/>
    </inertial>
    <visual>
      <origin rpy="0 0 0" xyz="0 0 0"/>
      <geometry>
        <mesh filename="file:///home/robotck/ros2_ws/install/h1_description/share/h1_description/meshes/visual/link-R6.STL"/>
      </geometry>
      <material name="">
        <color rgba="0.776470588235294 0.756862745098039 0.737254901960784 1"/>
      </material>
    </visual>
    <collision>
      <origin rpy="0 0 0" xyz="0 0 0"/>
      <geometry>
        <mesh filename="file:///home/robotck/ros2_ws/install/h1_description/share/h1_description/meshes/visual/link-R6.STL"/>
      </geometry>
    </collision>
  </link>
  <joint name="R-J6" type="revolute">
    <origin rpy="-1.5708 0 -1.5708" xyz="0 0 0"/>
    <parent link="link-R5"/>
    <child link="link-R6"/>
    <axis xyz="0 0 1"/>
    <limit effort="0" lower="-2" upper="2" velocity="0"/>
  </joint>
  <link name="link-R7">
    <inertial>
      <origin rpy="0 0 0" xyz="-1.17764460005164E-05 -4.94366788061917E-05 -0.0268906982201492"/>
      <mass value="0.640550089168939"/>
      <inertia ixx="0.000322001272956544" ixy="-1.70396644856445E-09" ixz="2.11407033295688E-08" iyy="0.000333657568863188" iyz="5.6325572115463E-07" izz="0.000473517445389121"/>
    </inertial>
    <visual>
      <origin rpy="0 0 0" xyz="0 0 0"/>
      <geometry>
        <mesh filename="file:///home/robotck/ros2_ws/install/h1_description/share/h1_description/meshes/visual/link-R7.STL"/>
      </geometry>
      <material name="">
        <color rgba="0.776470588235294 0.756862745098039 0.737254901960784 1"/>
      </material>
    </visual>
    <collision>
      <origin rpy="0 0 0" xyz="0 0 0"/>
      <geometry>
        <mesh filename="file:///home/robotck/ros2_ws/install/h1_description/share/h1_description/meshes/visual/link-R7.STL"/>
      </geometry>
    </collision>
  </link>
  <joint name="R-J7" type="revolute">
    <origin rpy="1.5708 -1.5708 0" xyz="0 -0.154 0"/>
    <parent link="link-R6"/>
    <child link="link-R7"/>
    <axis xyz="0 0 1"/>
    <limit effort="0" lower="-3.0543" upper="3.0543" velocity="0"/>
  </joint>
  <link name="link-L0">
    <inertial>
      <origin rpy="0 0 0" xyz="-8.87059234046067E-06 0.000550752555020795 0.0379327152282237"/>
      <mass value="3.4609012252728"/>
      <inertia ixx="0.00462447118331535" ixy="9.94202742834784E-07" ixz="-5.60268944341054E-06" iyy="0.00500473280410574" iyz="4.4126715549466E-05" izz="0.00508763431490107"/>
    </inertial>
    <visual>
      <origin rpy="0 0 0" xyz="0 0 0"/>
      <geometry>
        <mesh filename="file:///home/robotck/ros2_ws/install/h1_description/share/h1_description/meshes/visual/link-L0.STL"/>
      </geometry>
      <material name="">
        <color rgba="0.776470588235294 0.756862745098039 0.737254901960784 1"/>
      </material>
    </visual>
    <collision>
      <origin rpy="0 0 0" xyz="0 0 0"/>
      <geometry>
        <mesh filename="file:///home/robotck/ros2_ws/install/h1_description/share/h1_description/meshes/visual/link-L0.STL"/>
      </geometry>
    </collision>
  </link>
  <joint name="L-J0" type="fixed">
    <origin rpy="-3.1416 0 0" xyz="0 0.38 -0.075"/>
    <parent link="link-Body"/>
    <child link="link-L0"/>
    <axis xyz="0 0 0"/>
  </joint>
  <link name="link-L1">
    <inertial>
      <origin rpy="0 0 0" xyz="-0.00391495384336187 3.44953459122666E-05 -0.0356925083702135"/>
      <mass value="3.84687374350624"/>
      <inertia ixx="0.00397929510085391" ixy="1.32956168786287E-06" ixz="-2.11559421739801E-06" iyy="0.00326619674443425" iyz="1.14620028338654E-06" izz="0.00266637011180378"/>
    </inertial>
    <visual>
      <origin rpy="0 0 0" xyz="0 0 0"/>
      <geometry>
        <mesh filename="file:///home/robotck/ros2_ws/install/h1_description/share/h1_description/meshes/visual/link-L1.STL"/>
      </geometry>
      <material name="">
        <color rgba="0.776470588235294 0.756862745098039 0.737254901960784 1"/>
      </material>
    </visual>
    <collision>
      <origin rpy="0 0 0" xyz="0 0 0"/>
      <geometry>
        <mesh filename="file:///home/robotck/ros2_ws/install/h1_description/share/h1_description/meshes/visual/link-L1.STL"/>
      </geometry>
    </collision>
  </link>
  <joint name="L-J1" type="revolute">
    <origin rpy="0 0 0" xyz="0 0 0.172"/>
    <parent link="link-L0"/>
    <child link="link-L1"/>
    <axis xyz="0 0 1"/>
    <limit effort="0" lower="-3.0543" upper="3.0543" velocity="0"/>
  </joint>
  <link name="link-L2">
    <inertial>
      <origin rpy="0 0 0" xyz="-3.86565513488257E-07 -0.0452420554170123 -0.00669051472875721"/>
      <mass value="4.59473656084855"/>
      <inertia ixx="0.0149236633705579" ixy="-4.66016937621526E-06" ixz="6.6777760684643E-07" iyy="0.00622043746458328" iyz="0.00157051411090369" izz="0.0130507506384638"/>
    </inertial>
    <visual>
      <origin rpy="0 0 0" xyz="0 0 0"/>
      <geometry>
        <mesh filename="file:///home/robotck/ros2_ws/install/h1_description/share/h1_description/meshes/visual/link-L2.STL"/>
      </geometry>
      <material name="">
        <color rgba="0.776470588235294 0.756862745098039 0.737254901960784 1"/>
      </material>
    </visual>
    <collision>
      <origin rpy="0 0 0" xyz="0 0 0"/>
      <geometry>
        <mesh filename="file:///home/robotck/ros2_ws/install/h1_description/share/h1_description/meshes/visual/link-L2.STL"/>
      </geometry>
    </collision>
  </link>
  <joint name="L-J2" type="revolute">
    <origin rpy="-1.5708 0 1.5708" xyz="0 0 0"/>
    <parent link="link-L1"/>
    <child link="link-L2"/>
    <axis xyz="0 0 1"/>
    <limit effort="0" lower="-1.6" upper="1.6" velocity="0"/>
  </joint>
  <link name="link-L3">
    <inertial>
      <origin rpy="0 0 0" xyz="-0.00324047095788919 -0.00110288577937256 -0.081991801606545"/>
      <mass value="4.58543329469384"/>
      <inertia ixx="0.011536016884983" ixy="4.15752513490069E-06" ixz="-1.48969963644205E-05" iyy="0.0108939919537677" iyz="0.000234057856009124" izz="0.00358981276861222"/>
    </inertial>
    <visual>
      <origin rpy="0 0 0" xyz="0 0 0"/>
      <geometry>
        <mesh filename="file:///home/robotck/ros2_ws/install/h1_description/share/h1_description/meshes/visual/link-L3.STL"/>
      </geometry>
      <material name="">
        <color rgba="0.776470588235294 0.756862745098039 0.737254901960784 1"/>
      </material>
    </visual>
    <collision>
      <origin rpy="0 0 0" xyz="0 0 0"/>
      <geometry>
        <mesh filename="file:///home/robotck/ros2_ws/install/h1_description/share/h1_description/meshes/visual/link-L3.STL"/>
      </geometry>
    </collision>
  </link>
  <joint name="L-J3" type="revolute">
    <origin rpy="1.5708 1.5708 0" xyz="0 -0.3 0"/>
    <parent link="link-L2"/>
    <child link="link-L3"/>
    <axis xyz="0 0 1"/>
    <limit effort="0" lower="-3.0543" upper="3.0543" velocity="0"/>
  </joint>
  <link name="link-L4">
    <inertial>
      <origin rpy="0 0 0" xyz="3.1841633544194E-05 -0.0368779533256999 -0.013938744195014"/>
      <mass value="3.87071095191786"/>
      <inertia ixx="0.0111305435051538" ixy="-2.98707077310507E-06" ixz="-4.85932424382727E-06" iyy="0.00460974197047289" iyz="0.00198988284541413" izz="0.0099367079000926"/>
    </inertial>
    <visual>
      <origin rpy="0 0 0" xyz="0 0 0"/>
      <geometry>
        <mesh filename="file:///home/robotck/ros2_ws/install/h1_description/share/h1_description/meshes/visual/link-L4.STL"/>
      </geometry>
      <material name="">
        <color rgba="0.776470588235294 0.756862745098039 0.737254901960784 1"/>
      </material>
    </visual>
    <collision>
      <origin rpy="0 0 0" xyz="0 0 0"/>
      <geometry>
        <mesh filename="file:///home/robotck/ros2_ws/install/h1_description/share/h1_description/meshes/visual/link-L4.STL"/>
      </geometry>
    </collision>
  </link>
  <joint name="L-J4" type="revolute">
    <origin rpy="-1.5708 0 1.5708" xyz="0 0 0"/>
    <parent link="link-L3"/>
    <child link="link-L4"/>
    <axis xyz="0 0 1"/>
    <limit effort="0" lower="-2.2" upper="1.7" velocity="0"/>
  </joint>
  <link name="link-L5">
    <inertial>
      <origin rpy="0 0 0" xyz="-0.00322215689066343 -7.49487112514657E-05 -0.0572975679008711"/>
      <mass value="1.82124545231832"/>
      <inertia ixx="0.0027820863063144" ixy="7.08235437742543E-08" ixz="4.67880502096515E-05" iyy="0.00248903276284999" iyz="-8.97378635588735E-07" izz="0.00124650141864314"/>
    </inertial>
    <visual>
      <origin rpy="0 0 0" xyz="0 0 0"/>
      <geometry>
        <mesh filename="file:///home/robotck/ros2_ws/install/h1_description/share/h1_description/meshes/visual/link-L5.STL"/>
      </geometry>
      <material name="">
        <color rgba="0.776470588235294 0.756862745098039 0.737254901960784 1"/>
      </material>
    </visual>
    <collision>
      <origin rpy="0 0 0" xyz="0 0 0"/>
      <geometry>
        <mesh filename="file:///home/robotck/ros2_ws/install/h1_description/share/h1_description/meshes/visual/link-L5.STL"/>
      </geometry>
    </collision>
  </link>
  <joint name="L-J5" type="revolute">
    <origin rpy="1.5708 1.5708 0" xyz="0 -0.22 0"/>
    <parent link="link-L4"/>
    <child link="link-L5"/>
    <axis xyz="0 0 1"/>
    <limit effort="0" lower="-3.0543" upper="3.0543" velocity="0"/>
  </joint>
  <link name="link-L6">
    <inertial>
      <origin rpy="0 0 0" xyz="-9.36842095644597E-06 -0.0325947019861459 -0.013346899157544"/>
      <mass value="2.86918680878108"/>
      <inertia ixx="0.00331600824470316" ixy="-5.37053935091679E-07" ixz="1.3474042330072E-06" iyy="0.00200841766148088" iyz="0.00055806673279974" izz="0.00366760091811487"/>
    </inertial>
    <visual>
      <origin rpy="0 0 0" xyz="0 0 0"/>
      <geometry>
        <mesh filename="file:///home/robotck/ros2_ws/install/h1_description/share/h1_description/meshes/visual/link-L6.STL"/>
      </geometry>
      <material name="">
        <color rgba="0.776470588235294 0.756862745098039 0.737254901960784 1"/>
      </material>
    </visual>
    <collision>
      <origin rpy="0 0 0" xyz="0 0 0"/>
      <geometry>
        <mesh filename="file:///home/robotck/ros2_ws/install/h1_description/share/h1_description/meshes/visual/link-L6.STL"/>
      </geometry>
    </collision>
  </link>
  <joint name="L-J6" type="revolute">
    <origin rpy="-1.5708 0 1.5708" xyz="0 0 0"/>
    <parent link="link-L5"/>
    <child link="link-L6"/>
    <axis xyz="0 0 1"/>
    <limit effort="0" lower="-2" upper="2" velocity="0"/>
  </joint>
  <link name="link-L7">
    <inertial>
      <origin rpy="0 0 0" xyz="1.17764431016314E-05 4.94366771461863E-05 -0.0268906982202844"/>
      <mass value="0.640550089261562"/>
      <inertia ixx="0.000322001272975965" ixy="-1.70398909748883E-09" ixz="-2.11406870898951E-08" iyy="0.000333657568909658" iyz="-5.63255711862325E-07" izz="0.000473517445441665"/>
    </inertial>
    <visual>
      <origin rpy="0 0 0" xyz="0 0 0"/>
      <geometry>
        <mesh filename="file:///home/robotck/ros2_ws/install/h1_description/share/h1_description/meshes/visual/link-L7.STL"/>
      </geometry>
      <material name="">
        <color rgba="0.776470588235294 0.756862745098039 0.737254901960784 1"/>
      </material>
    </visual>
    <collision>
      <origin rpy="0 0 0" xyz="0 0 0"/>
      <geometry>
        <mesh filename="file:///home/robotck/ros2_ws/install/h1_description/share/h1_description/meshes/visual/link-L7.STL"/>
      </geometry>
    </collision>
  </link>
  <joint name="L-J7" type="revolute">
    <origin rpy="1.5708 1.5708 0" xyz="0 -0.154 0"/>
    <parent link="link-L6"/>
    <child link="link-L7"/>
    <axis xyz="0 0 1"/>
    <limit effort="0" lower="-3.0543" upper="3.0543" velocity="0"/>
  </joint>
  <link name="link-H0">
    <inertial>
      <origin rpy="0 0 0" xyz="2.77417069748782E-06 -0.00801860812416875 -0.0404494724916487"/>
      <mass value="0.533047406480681"/>
      <inertia ixx="0.000692103895288128" ixy="-1.48199773270518E-08" ixz="-2.39235593860357E-08" iyy="0.000709375331980261" iyz="4.60043825948019E-05" izz="0.000267854166625837"/>
    </inertial>
    <visual>
      <origin rpy="0 0 0" xyz="0 0 0"/>
      <geometry>
        <mesh filename="file:///home/robotck/ros2_ws/install/h1_description/share/h1_description/meshes/visual/link-H0.STL"/>
      </geometry>
      <material name="">
        <color rgba="0.792156862745098 0.819607843137255 0.933333333333333 1"/>
      </material>
    </visual>
    <collision>
      <origin rpy="0 0 0" xyz="0 0 0"/>
      <geometry>
        <mesh filename="file:///home/robotck/ros2_ws/install/h1_description/share/h1_description/meshes/visual/link-H0.STL"/>
      </geometry>
    </collision>
  </link>
  <joint name="H-J1" type="revolute">
    <origin rpy="-1.5708 0 0" xyz="0 0.535 0"/>
    <parent link="link-Body"/>
    <child link="link-H0"/>
    <axis xyz="0 0 1"/>
    <limit effort="0" lower="-1" upper="1" velocity="0"/>
  </joint>
  <link name="link-H1">
    <inertial>
      <origin rpy="0 0 0" xyz="0.0098437998944257 -0.0888857409529311 0.00256703993477317"/>
      <mass value="0.436772949848794"/>
      <inertia ixx="0.000635413918611848" ixy="1.04102465959542E-05" ixz="-2.94933871253236E-07" iyy="0.000648875246390544" iyz="1.19746555869357E-05" izz="0.000441756556005861"/>
    </inertial>
    <visual>
      <origin rpy="0 0 0" xyz="0 0 0"/>
      <geometry>
        <mesh filename="file:///home/robotck/ros2_ws/install/h1_description/share/h1_description/meshes/visual/link-H1.STL"/>
      </geometry>
      <material name="">
        <color rgba="0.792156862745098 0.819607843137255 0.933333333333333 1"/>
      </material>
    </visual>
    <collision>
      <origin rpy="0 0 0" xyz="0 0 0"/>
      <geometry>
        <mesh filename="file:///home/robotck/ros2_ws/install/h1_description/share/h1_description/meshes/visual/link-H1.STL"/>
      </geometry>
    </collision>
  </link>
  <joint name="H-J2" type="revolute">
    <origin rpy="-1.5708 0 0" xyz="0 0 0"/>
    <parent link="link-H0"/>
    <child link="link-H1"/>
    <axis xyz="0 0 1"/>
    <limit effort="0" lower="-1" upper="1" velocity="0"/>
  </joint>
  <!-- <link name="base_footprint">
    <visual>
        <origin xyz="0 0 0" rpy="0 0 0" />
        <geometry>
            <box size="0.001 0.001 0.001" />
        </geometry>
    </visual>
  </link>
  <joint name="arm_to_inspire_hand_joint" type="fixed">
    <origin xyz="0 0 0" rpy="-1.57 0 -1.57" />
    <parent link="base_footprint"/>
    <child link="R_hand_base_link"/>
  </joint> -->
  <link name="R_hand_base_link">
    <inertial>
      <origin rpy="0 0 0" xyz="-0.0025264 -0.066047 0.0019598"/>
      <mass value="0.14143"/>
      <inertia ixx="0.00012281" ixy="2.1711E-06" ixz="1.7709E-06" iyy="8.3832E-05" iyz="-1.6551E-06" izz="7.6663E-05"/>
    </inertial>
    <visual>
      <origin rpy="0 0 0" xyz="0 0 0"/>
      <geometry>
        <mesh filename="file:///home/robotck/ros2_ws/install/inspire_hand_description/share/inspire_hand_description/meshes/visual/R_hand_base_link.STL"/>
      </geometry>
      <material name="">
        <color rgba="1 1 1 1"/>
      </material>
    </visual>
    <collision>
      <origin rpy="0 0 0" xyz="0 0 0"/>
      <geometry>
        <mesh filename="file:///home/robotck/ros2_ws/install/inspire_hand_description/share/inspire_hand_description/meshes/visual/R_hand_base_link.STL"/>
      </geometry>
    </collision>
  </link>
  <link name="R_thumb_proximal_base">
    <inertial>
      <origin rpy="0 0 0" xyz="-0.0048064 0.0009382 -0.00757"/>
      <mass value="0.0018869"/>
      <inertia ixx="5.816E-08" ixy="1.4539E-08" ixz="4.491E-09" iyy="7.9161E-08" iyz="-1.8727E-09" izz="6.7433E-08"/>
    </inertial>
    <visual>
      <origin rpy="0 0 0" xyz="0 0 0"/>
      <geometry>
        <mesh filename="file:///home/robotck/ros2_ws/install/inspire_hand_description/share/inspire_hand_description/meshes/visual/Link11.STL"/>
      </geometry>
      <material name="">
        <color rgba="1 1 1 1"/>
      </material>
    </visual>
    <collision>
      <origin rpy="0 0 0" xyz="0 0 0"/>
      <geometry>
        <mesh filename="file:///home/robotck/ros2_ws/install/inspire_hand_description/share/inspire_hand_description/meshes/visual/Link11.STL"/>
      </geometry>
    </collision>
  </link>
  <joint name="hand_joint6" type="revolute">
    <origin rpy="1.5708 -1.5708 0" xyz="-0.01696 -0.0691 -0.02045"/>
    <parent link="R_hand_base_link"/>
    <child link="R_thumb_proximal_base"/>
    <axis xyz="0 0 -1"/>
    <limit effort="1" lower="-0.1" upper="1.3" velocity="0.5"/>
  </joint>
  <link name="R_thumb_proximal">
    <inertial>
      <origin rpy="0 0 0" xyz="0.021932 0.012785 -0.0080386"/>
      <mass value="0.0066075"/>
      <inertia ixx="1.5686E-06" ixy="-7.8296E-07" ixz="8.9143E-10" iyy="1.7353E-06" iyz="-1.0191E-09" izz="2.786E-06"/>
    </inertial>
    <visual>
      <origin rpy="0 0 0" xyz="0 0 0"/>
      <geometry>
        <mesh filename="file:///home/robotck/ros2_ws/install/inspire_hand_description/share/inspire_hand_description/meshes/visual/Link12.STL"/>
      </geometry>
      <material name="">
        <color rgba="1 1 1 1"/>
      </material>
    </visual>
    <collision>
      <origin rpy="0 0 0" xyz="0 0 0"/>
      <geometry>
        <mesh filename="file:///home/robotck/ros2_ws/install/inspire_hand_description/share/inspire_hand_description/meshes/visual/Link12.STL"/>
      </geometry>
    </collision>
  </link>
  <joint name="hand_joint5" type="revolute">
    <origin rpy="1.5708 0 2.8587" xyz="-0.0088099 0.010892 -0.00925"/>
    <parent link="R_thumb_proximal_base"/>
    <child link="R_thumb_proximal"/>
    <axis xyz="0 0 1"/>
    <limit effort="1" lower="-0.1" upper="0.6" velocity="0.5"/>
  </joint>
  <link name="R_thumb_intermediate">
    <inertial>
      <origin rpy="0 0 0" xyz="0.0095544 -0.0016282 -0.0071997"/>
      <mass value="0.0037847"/>
      <inertia ixx="3.6981E-07" ixy="-9.8581E-08" ixz="-4.7469E-12" iyy="3.2394E-07" iyz="1.0939E-12" izz="4.6531E-07"/>
    </inertial>
    <visual>
      <origin rpy="0 0 0" xyz="0 0 0"/>
      <geometry>
        <mesh filename="file:///home/robotck/ros2_ws/install/inspire_hand_description/share/inspire_hand_description/meshes/visual/Link13.STL"/>
      </geometry>
      <material name="">
        <color rgba="1 1 1 1"/>
      </material>
    </visual>
    <collision>
      <origin rpy="0 0 0" xyz="0 0 0"/>
      <geometry>
        <mesh filename="file:///home/robotck/ros2_ws/install/inspire_hand_description/share/inspire_hand_description/meshes/visual/Link13.STL"/>
      </geometry>
    </collision>
  </link>
  <joint name="R_thumb_intermediate_joint" type="revolute">
    <origin rpy="0 0 0" xyz="0.04407 0.034553 -0.0008"/>
    <parent link="R_thumb_proximal"/>
    <child link="R_thumb_intermediate"/>
    <axis xyz="0 0 1"/>
    <limit effort="1" lower="0" upper="0.8" velocity="0.5"/>
    <mimic joint="hand_joint5" multiplier="1.6" offset="0"/>
  </joint>
  <link name="R_thumb_distal">
    <inertial>
      <origin rpy="0 0 0" xyz="0.0092888 0.0049529 -0.0060033"/>
      <mass value="0.0033441"/>
      <inertia ixx="1.3632E-07" ixy="-5.6788E-08" ixz="-9.2764E-11" iyy="1.4052E-07" iyz="-1.2283E-10" izz="2.0026E-07"/>
    </inertial>
    <visual>
      <origin rpy="0 0 0" xyz="0 0 0"/>
      <geometry>
        <mesh filename="file:///home/robotck/ros2_ws/install/inspire_hand_description/share/inspire_hand_description/meshes/visual/Link14.STL"/>
      </geometry>
      <material name="">
        <color rgba="1 1 1 1"/>
      </material>
    </visual>
    <collision>
      <origin rpy="0 0 0" xyz="0 0 0"/>
      <geometry>
        <mesh filename="file:///home/robotck/ros2_ws/install/inspire_hand_description/share/inspire_hand_description/meshes/visual/Link14.STL"/>
      </geometry>
    </collision>
  </link>
  <joint name="R_thumb_distal_joint" type="revolute">
    <origin rpy="0 0 0" xyz="0.020248 0.010156 -0.0012"/>
    <parent link="R_thumb_intermediate"/>
    <child link="R_thumb_distal"/>
    <axis xyz="0 0 1"/>
    <limit effort="1" lower="0" upper="1.2" velocity="0.5"/>
    <mimic joint="hand_joint5" multiplier="2.4" offset="0"/>
  </joint>
  <link name="R_index_proximal">
    <inertial>
      <origin rpy="0 0 0" xyz="0.0012259 0.011942 -0.0060001"/>
      <mass value="0.0042403"/>
      <inertia ixx="6.6232E-07" ixy="-1.5775E-08" ixz="1.8515E-12" iyy="2.1146E-07" iyz="-5.0828E-12" izz="6.9398E-07"/>
    </inertial>
    <visual>
      <origin rpy="0 0 0" xyz="0 0 0"/>
      <geometry>
        <mesh filename="file:///home/robotck/ros2_ws/install/inspire_hand_description/share/inspire_hand_description/meshes/visual/Link15.STL"/>
      </geometry>
      <material name="">
        <color rgba="1 1 1 1"/>
      </material>
    </visual>
    <collision>
      <origin rpy="0 0 0" xyz="0 0 0"/>
      <geometry>
        <mesh filename="file:///home/robotck/ros2_ws/install/inspire_hand_description/share/inspire_hand_description/meshes/visual/Link15.STL"/>
      </geometry>
    </collision>
  </link>
  <joint name="hand_joint4" type="revolute">
    <origin rpy="-3.1067 0 0" xyz="0.00028533 -0.13653 -0.032268"/>
    <parent link="R_hand_base_link"/>
    <child link="R_index_proximal"/>
    <axis xyz="0 0 1"/>
    <limit effort="1" lower="0" upper="1.7" velocity="0.5"/>
  </joint>
  <link name="R_index_intermediate">
    <inertial>
      <origin rpy="0 0 0" xyz="0.0019697 0.019589 -0.005"/>
      <mass value="0.0045683"/>
      <inertia ixx="7.6111E-07" ixy="8.7637E-08" ixz="-3.7751E-13" iyy="9.6076E-08" iyz="9.9444E-13" izz="7.8179E-07"/>
    </inertial>
    <visual>
      <origin rpy="0 0 0" xyz="0 0 0"/>
      <geometry>
        <mesh filename="file:///home/robotck/ros2_ws/install/inspire_hand_description/share/inspire_hand_description/meshes/visual/Link16.STL"/>
      </geometry>
      <material name="">
        <color rgba="1 1 1 1"/>
      </material>
    </visual>
    <collision>
      <origin rpy="0 0 0" xyz="0 0 0"/>
      <geometry>
        <mesh filename="file:///home/robotck/ros2_ws/install/inspire_hand_description/share/inspire_hand_description/meshes/visual/Link16.STL"/>
      </geometry>
    </collision>
  </link>
  <joint name="R_index_intermediate_joint" type="revolute">
    <origin rpy="0 0 0" xyz="-0.0026138 0.032026 -0.001"/>
    <parent link="R_index_proximal"/>
    <child link="R_index_intermediate"/>
    <axis xyz="0 0 1"/>
    <limit effort="1" lower="0" upper="1.7" velocity="0.5"/>
    <mimic joint="hand_joint4" multiplier="1" offset="0"/>
  </joint>
  <link name="R_middle_proximal">
    <inertial>
      <origin rpy="0 0 0" xyz="0.001297 0.011934 -0.0060001"/>
      <mass value="0.0042403"/>
      <inertia ixx="6.6211E-07" ixy="-1.8461E-08" ixz="1.8002E-12" iyy="2.1167E-07" iyz="-6.6808E-12" izz="6.9397E-07"/>
    </inertial>
    <visual>
      <origin rpy="0 0 0" xyz="0 0 0"/>
      <geometry>
        <mesh filename="file:///home/robotck/ros2_ws/install/inspire_hand_description/share/inspire_hand_description/meshes/visual/Link17.STL"/>
      </geometry>
      <material name="">
        <color rgba="1 1 1 1"/>
      </material>
    </visual>
    <collision>
      <origin rpy="0 0 0" xyz="0 0 0"/>
      <geometry>
        <mesh filename="file:///home/robotck/ros2_ws/install/inspire_hand_description/share/inspire_hand_description/meshes/visual/Link17.STL"/>
      </geometry>
    </collision>
  </link>
  <joint name="hand_joint3" type="revolute">
    <origin rpy="-3.1416 0 0" xyz="0.00028533 -0.1371 -0.01295"/>
    <parent link="R_hand_base_link"/>
    <child link="R_middle_proximal"/>
    <axis xyz="0 0 1"/>
    <limit effort="1" lower="0" upper="1.7" velocity="0.5"/>
  </joint>
  <link name="R_middle_intermediate">
    <inertial>
      <origin rpy="0 0 0" xyz="0.001921 0.020796 -0.005"/>
      <mass value="0.0050396"/>
      <inertia ixx="9.5822E-07" ixy="1.1425E-07" ixz="-2.4791E-12" iyy="1.0646E-07" iyz="5.9173E-12" izz="9.8384E-07"/>
    </inertial>
    <visual>
      <origin rpy="0 0 0" xyz="0 0 0"/>
      <geometry>
        <mesh filename="file:///home/robotck/ros2_ws/install/inspire_hand_description/share/inspire_hand_description/meshes/visual/Link18.STL"/>
      </geometry>
      <material name="">
        <color rgba="1 1 1 1"/>
      </material>
    </visual>
    <collision>
      <origin rpy="0 0 0" xyz="0 0 0"/>
      <geometry>
        <mesh filename="file:///home/robotck/ros2_ws/install/inspire_hand_description/share/inspire_hand_description/meshes/visual/Link18.STL"/>
      </geometry>
    </collision>
  </link>
  <joint name="R_middle_intermediate_joint" type="revolute">
    <origin rpy="0 0 0" xyz="-0.0024229 0.032041 -0.001"/>
    <parent link="R_middle_proximal"/>
    <child link="R_middle_intermediate"/>
    <axis xyz="0 0 1"/>
    <limit effort="1" lower="0" upper="1.7" velocity="0.5"/>
    <mimic joint="hand_joint3" multiplier="1" offset="0"/>
  </joint>
  <link name="R_ring_proximal">
    <inertial>
      <origin rpy="0 0 0" xyz="0.001297 0.011934 -0.0060002"/>
      <mass value="0.0042403"/>
      <inertia ixx="6.6211E-07" ixy="-1.8461E-08" ixz="1.5793E-12" iyy="2.1167E-07" iyz="-6.6868E-12" izz="6.9397E-07"/>
    </inertial>
    <visual>
      <origin rpy="0 0 0" xyz="0 0 0"/>
      <geometry>
        <mesh filename="file:///home/robotck/ros2_ws/install/inspire_hand_description/share/inspire_hand_description/meshes/visual/Link19.STL"/>
      </geometry>
      <material name="">
        <color rgba="1 1 1 1"/>
      </material>
    </visual>
    <collision>
      <origin rpy="0 0 0" xyz="0 0 0"/>
      <geometry>
        <mesh filename="file:///home/robotck/ros2_ws/install/inspire_hand_description/share/inspire_hand_description/meshes/visual/Link19.STL"/>
      </geometry>
    </collision>
  </link>
  <joint name="hand_joint2" type="revolute">
    <origin rpy="3.0892 0 0" xyz="0.00028533 -0.13691 0.0062872"/>
    <parent link="R_hand_base_link"/>
    <child link="R_ring_proximal"/>
    <axis xyz="0 0 1"/>
    <limit effort="1" lower="0" upper="1.7" velocity="0.5"/>
  </joint>
  <link name="R_ring_intermediate">
    <inertial>
      <origin rpy="0 0 0" xyz="0.0021753 0.019567 -0.005"/>
      <mass value="0.0045683"/>
      <inertia ixx="7.6286E-07" ixy="8.0635E-08" ixz="-6.1562E-13" iyy="9.431E-08" iyz="5.8619E-13" izz="7.8177E-07"/>
    </inertial>
    <visual>
      <origin rpy="0 0 0" xyz="0 0 0"/>
      <geometry>
        <mesh filename="file:///home/robotck/ros2_ws/install/inspire_hand_description/share/inspire_hand_description/meshes/visual/Link20.STL"/>
      </geometry>
      <material name="">
        <color rgba="1 1 1 1"/>
      </material>
    </visual>
    <collision>
      <origin rpy="0 0 0" xyz="0 0 0"/>
      <geometry>
        <mesh filename="file:///home/robotck/ros2_ws/install/inspire_hand_description/share/inspire_hand_description/meshes/visual/Link20.STL"/>
      </geometry>
    </collision>
  </link>
  <joint name="R_ring_intermediate_joint" type="revolute">
    <origin rpy="0 0 0" xyz="-0.0024229 0.032041 -0.001"/>
    <parent link="R_ring_proximal"/>
    <child link="R_ring_intermediate"/>
    <axis xyz="0 0 1"/>
    <limit effort="1" lower="0" upper="1.7" velocity="0.5"/>
    <mimic joint="hand_joint2" multiplier="1" offset="0"/>
  </joint>
  <link name="R_pinky_proximal">
    <inertial>
      <origin rpy="0 0 0" xyz="0.001297 0.011934 -0.0060001"/>
      <mass value="0.0042403"/>
      <inertia ixx="6.6211E-07" ixy="-1.8461E-08" ixz="1.6907E-12" iyy="2.1167E-07" iyz="-6.9334E-12" izz="6.9397E-07"/>
    </inertial>
    <visual>
      <origin rpy="0 0 0" xyz="0 0 0"/>
      <geometry>
        <mesh filename="file:///home/robotck/ros2_ws/install/inspire_hand_description/share/inspire_hand_description/meshes/visual/Link21.STL"/>
      </geometry>
      <material name="">
        <color rgba="1 1 1 1"/>
      </material>
    </visual>
    <collision>
      <origin rpy="0 0 0" xyz="0 0 0"/>
      <geometry>
        <mesh filename="file:///home/robotck/ros2_ws/install/inspire_hand_description/share/inspire_hand_description/meshes/visual/Link21.STL"/>
      </geometry>
    </collision>
  </link>
  <joint name="hand_joint1" type="revolute">
    <origin rpy="3.0369 0 0" xyz="0.00028533 -0.13571 0.025488"/>
    <parent link="R_hand_base_link"/>
    <child link="R_pinky_proximal"/>
    <axis xyz="0 0 1"/>
    <limit effort="1" lower="0" upper="1.7" velocity="0.5"/>
  </joint>
  <link name="R_pinky_intermediate">
    <inertial>
      <origin rpy="0 0 0" xyz="0.0024748 0.016203 -0.0050031"/>
      <mass value="0.0035996"/>
      <inertia ixx="4.3913E-07" ixy="4.1418E-08" ixz="3.7168E-11" iyy="7.0247E-08" iyz="5.8613E-11" izz="4.4867E-07"/>
    </inertial>
    <visual>
      <origin rpy="0 0 0" xyz="0 0 0"/>
      <geometry>
        <mesh filename="file:///home/robotck/ros2_ws/install/inspire_hand_description/share/inspire_hand_description/meshes/visual/Link22.STL"/>
      </geometry>
      <material name="">
        <color rgba="1 1 1 1"/>
      </material>
    </visual>
    <collision>
      <origin rpy="0 0 0" xyz="0 0 0"/>
      <geometry>
        <mesh filename="file:///home/robotck/ros2_ws/install/inspire_hand_description/share/inspire_hand_description/meshes/visual/Link22.STL"/>
      </geometry>
    </collision>
  </link>
  <joint name="R_pinky_intermediate_joint" type="revolute">
    <origin rpy="0 0 0" xyz="-0.0024229 0.032041 -0.001"/>
    <parent link="R_pinky_proximal"/>
    <child link="R_pinky_intermediate"/>
    <axis xyz="0 0 1"/>
    <limit effort="1" lower="0" upper="1.7" velocity="0.5"/>
    <mimic joint="hand_joint1" multiplier="1" offset="0"/>
  </joint>
  <!-- <link name="base_footprint">
    <visual>
        <origin xyz="0 0 0" rpy="0 0 0" />
        <geometry>
            <box size="0.001 0.001 0.001" />
        </geometry>
    </visual>
  </link>
  <joint name="arm_to_hand_e" type="fixed">
    <origin xyz="0 0 0.00695" rpy="0 0 0" />
    <parent link="base_footprint"/>
    <child link="hand_e_link"/>
  </joint> -->
  <link name="hand_e_link">
    <inertial>
      <origin rpy="0 0 0" xyz="0 0 0.04607"/>
      <mass value="0.86387"/>
      <inertia ixx="1017560E-9" ixy="0" ixz="2235E-9" iyy="1028041E-9" iyz="0" izz="489810E-9"/>
    </inertial>
    <visual>
      <origin rpy="0 0 0" xyz="0 0 0"/>
      <geometry>
        <mesh filename="file:///home/robotck/ros2_ws/install/robotiq_gripper_description/share/robotiq_gripper_description/meshes/visual/hand-e.dae" scale="1.0 1.0 1.0"/>
      </geometry>
      <material name="Dark">
        <color rgba=".1 0.1 0.1 1.0"/>
      </material>
    </visual>
    <collision>
      <origin rpy="0 0 0" xyz="0 0 0"/>
      <geometry>
        <mesh filename="file:///home/robotck/ros2_ws/install/robotiq_gripper_description/share/robotiq_gripper_description/meshes/visual/hand-e.dae" scale="1.0 1.0 1.0"/>
      </geometry>
    </collision>
  </link>
  <link name="hande_left_finger">
    <inertial>
      <origin rpy="0 0 0" xyz="0.02262 -0.00759 0.00738"/>
      <mass value="0.03804"/>
      <inertia ixx="13567E-9" ixy="1849E-9" ixz="3622E-9" iyy="15784E-9" iyz="3616E-9" izz="7478E-9"/>
    </inertial>
    <visual>
      <origin rpy="0 0 0" xyz="0 0 0"/>
      <geometry>
        <mesh filename="file:///home/robotck/ros2_ws/install/robotiq_gripper_description/share/robotiq_gripper_description/meshes/visual/finger_1.dae" scale="1.0 1.0 1.0"/>
      </geometry>
      <material name="DarkGray">
        <color rgba=".4 0.4 0.4 1.0"/>
      </material>
    </visual>
    <collision>
      <origin rpy="0 0 0" xyz="0 0 0"/>
      <geometry>
        <mesh filename="file:///home/robotck/ros2_ws/install/robotiq_gripper_description/share/robotiq_gripper_description/meshes/visual/finger_1.dae" scale="1.0 1.0 1.0"/>
      </geometry>
    </collision>
  </link>
  <link name="hande_right_finger">
    <inertial>
      <origin rpy="0 0 0" xyz="-0.02262 0.00759 0.00738"/>
      <mass value="0.03804"/>
      <inertia ixx="13567E-9" ixy="1849E-9" ixz="-3622E-9" iyy="15784E-9" iyz="-3616E-9" izz="7478E-9"/>
    </inertial>
    <visual>
      <origin rpy="0 0 0" xyz="0 0 0"/>
      <geometry>
        <mesh filename="file:///home/robotck/ros2_ws/install/robotiq_gripper_description/share/robotiq_gripper_description/meshes/visual/finger_2.dae" scale="1.0 1.0 1.0"/>
      </geometry>
      <material name="DarkGray">
        <color rgba=".4 0.4 0.4 1.0"/>
      </material>
    </visual>
    <collision>
      <origin rpy="0 0 0" xyz="0 0 0"/>
      <geometry>
        <mesh filename="file:///home/robotck/ros2_ws/install/robotiq_gripper_description/share/robotiq_gripper_description/meshes/visual/finger_2.dae" scale="1.0 1.0 1.0"/>
      </geometry>
    </collision>
  </link>
  <joint name="gripper_joint" type="prismatic">
    <origin rpy="0 0 0" xyz="0 0 0.099"/>
    <parent link="hand_e_link"/>
    <child link="hande_left_finger"/>
    <axis xyz="-1 0 0"/>
    <limit effort="130" lower="0" upper="0.025" velocity="0.15"/>
  </joint>
  <joint name="hande_right_finger_joint" type="prismatic">
    <origin rpy="0 0 0" xyz="0 0 0.099"/>
    <parent link="hand_e_link"/>
    <child link="hande_right_finger"/>
    <axis xyz="1 0 0"/>
    <limit effort="130" lower="0" upper="0.025" velocity="0.15"/>
    <mimic joint="gripper_joint" multiplier="1" offset="0"/>
  </joint>
  <joint name="gripper_connect_joint" type="fixed">
    <origin rpy="0 0 0" xyz="0 0 0"/>
    <!-- <origin xyz="0 0 0.00695" rpy="0 0 0" /> -->
    <parent link="link-L7"/>
    <child link="hand_e_link"/>
  </joint>
  <joint name="hand_connect_joint" type="fixed">
    <!-- <origin xyz="0 0 0" rpy="-1.57 0 -1.57" /> -->
    <origin rpy="-1.57 0 1.57" xyz="0 0 0"/>
    <parent link="link-R7"/>
    <child link="R_hand_base_link"/>
  </joint>
</robot>
