<?xml version="1.0" encoding="utf-8"?>
<!-- This URDF was automatically created by SolidWorks to URDF Exporter! Originally created by Stephen Brawner (brawner@gmail.com) 
     Commit Version: 1.5.1-0-g916b5db  Build Version: 1.5.7152.31018
     For more information, please see http://wiki.ros.org/sw_urdf_exporter -->
<robot
  name="SIA_robot">
  <link
    name="base_link">
    <inertial>
      <origin
        xyz="0.00608770814142283 0.00345294437108543 0.36719318766884"
        rpy="0 0 0" />
      <mass
        value="5.08372108708452" />
      <inertia
        ixx="0.0681483796497588"
        ixy="-6.583736565642E-05"
        ixz="-0.00435126206558179"
        iyy="0.0562781365647336"
        iyz="-0.000288236319946359"
        izz="0.0317831828027757" />
    </inertial>
    <visual>
      <origin
        xyz="0 0 0"
        rpy="0 0 0" />
      <geometry>
        <mesh
          filename="package://SIA_robot/meshes/base_link.STL" />
      </geometry>
      <material
        name="">
        <color
          rgba="0.792156862745098 0.819607843137255 0.933333333333333 1" />
      </material>
    </visual>
    <collision>
      <origin
        xyz="0 0 0"
        rpy="0 0 0" />
      <geometry>
        <mesh
          filename="package://SIA_robot/meshes/base_link.STL" />
      </geometry>
    </collision>
  </link>
  <link
    name="Link-Body">
    <inertial>
      <origin
        xyz="-0.000158222660641598 -9.98278990236623E-06 -0.249624469139269"
        rpy="0 0 0" />
      <mass
        value="3.41445688652289" />
      <inertia
        ixx="0.0248203808488518"
        ixy="-2.36063985454879E-08"
        ixz="-0.000749290486872422"
        iyy="0.01388988449036"
        iyz="7.57304943520522E-07"
        izz="0.0185938049482952" />
    </inertial>
    <visual>
      <origin
        xyz="0 0 0"
        rpy="0 0 0" />
      <geometry>
        <mesh
          filename="package://SIA_robot/meshes/Link-Body.STL" />
      </geometry>
      <material
        name="">
        <color
          rgba="0.792156862745098 0.819607843137255 0.933333333333333 1" />
      </material>
    </visual>
    <collision>
      <origin
        xyz="0 0 0"
        rpy="0 0 0" />
      <geometry>
        <mesh
          filename="package://SIA_robot/meshes/Link-Body.STL" />
      </geometry>
    </collision>
  </link>
  <joint
    name="B0"
    type="prismatic">
    <origin
      xyz="0 0 0.95385"
      rpy="0 0 0" />
    <parent
      link="base_link" />
    <child
      link="Link-Body" />
    <axis
      xyz="0 0 1" />
    <limit
      lower="-0.05"
      upper="0.21"
      effort="0"
      velocity="0" />
  </joint>
  <link
    name="link-R0">
    <inertial>
      <origin
        xyz="-1.6666483421104E-05 -0.000428575028514344 0.0387665520212092"
        rpy="0 0 0" />
      <mass
        value="4.48243687136842" />
      <inertia
        ixx="0.00516757527508353"
        ixy="-6.99003877944147E-07"
        ixz="-1.89822417332752E-06"
        iyy="0.00522193992152092"
        iyz="-4.82183712983688E-05"
        izz="0.00566118382384461" />
    </inertial>
    <visual>
      <origin
        xyz="0 0 0"
        rpy="0 0 0" />
      <geometry>
        <mesh
          filename="package://SIA_robot/meshes/link-R0.STL" />
      </geometry>
      <material
        name="">
        <color
          rgba="1 1 1 1" />
      </material>
    </visual>
    <collision>
      <origin
        xyz="0 0 0"
        rpy="0 0 0" />
      <geometry>
        <mesh
          filename="package://SIA_robot/meshes/link-R0.STL" />
      </geometry>
    </collision>
  </link>
  <joint
    name="R-J0"
    type="fixed">
    <origin
      xyz="0 -0.09 -0.075"
      rpy="1.5708 0 0" />
    <parent
      link="Link-Body" />
    <child
      link="link-R0" />
    <axis
      xyz="0 0 0" />
  </joint>
  <link
    name="link-R1">
    <inertial>
      <origin
        xyz="-3.21247843160233E-06 0.00052447279922216 -0.0441242557856534"
        rpy="0 0 0" />
      <mass
        value="3.29940267206034" />
      <inertia
        ixx="0.00538935884644845"
        ixy="-3.40948002179596E-09"
        ixz="-4.54525514109768E-07"
        iyy="0.00597533433884467"
        iyz="-7.64162243136917E-05"
        izz="0.00258712975386507" />
    </inertial>
    <visual>
      <origin
        xyz="0 0 0"
        rpy="0 0 0" />
      <geometry>
        <mesh
          filename="package://SIA_robot/meshes/link-R1.STL" />
      </geometry>
      <material
        name="">
        <color
          rgba="1 1 1 1" />
      </material>
    </visual>
    <collision>
      <origin
        xyz="0 0 0"
        rpy="0 0 0" />
      <geometry>
        <mesh
          filename="package://SIA_robot/meshes/link-R1.STL" />
      </geometry>
    </collision>
  </link>
  <joint
    name="R-J1"
    type="revolute">
    <origin
      xyz="0 0 0.172"
      rpy="0 0 -1.5708" />
    <parent
      link="link-R0" />
    <child
      link="link-R1" />
    <axis
      xyz="0 0 1" />
    <limit
      lower="-3.0543"
      upper="3.0543"
      effort="0"
      velocity="0" />
  </joint>
  <link
    name="link-R2">
    <inertial>
      <origin
        xyz="-1.21016987286726E-06 -0.0553985267336023 -0.00166564475227283"
        rpy="0 0 0" />
      <mass
        value="5.63523258516487" />
      <inertia
        ixx="0.0152384536230366"
        ixy="-1.14870185368696E-06"
        ixz="-2.6851571084856E-08"
        iyy="0.00674678421570552"
        iyz="0.000400962979098618"
        izz="0.0142810956251759" />
    </inertial>
    <visual>
      <origin
        xyz="0 0 0"
        rpy="0 0 0" />
      <geometry>
        <mesh
          filename="package://SIA_robot/meshes/link-R2.STL" />
      </geometry>
      <material
        name="">
        <color
          rgba="0.776470588235294 0.756862745098039 0.737254901960784 1" />
      </material>
    </visual>
    <collision>
      <origin
        xyz="0 0 0"
        rpy="0 0 0" />
      <geometry>
        <mesh
          filename="package://SIA_robot/meshes/link-R2.STL" />
      </geometry>
    </collision>
  </link>
  <joint
    name="R-J2"
    type="revolute">
    <origin
      xyz="0 0 0"
      rpy="-1.5708 0 0" />
    <parent
      link="link-R1" />
    <child
      link="link-R2" />
    <axis
      xyz="0 0 1" />
    <limit
      lower="-1.8246"
      upper="1.8246"
      effort="0"
      velocity="0" />
  </joint>
  <link
    name="link-R3">
    <inertial>
      <origin
        xyz="-0.00236928911888323 0.000256017152003125 -0.0989215512578252"
        rpy="0 0 0" />
      <mass
        value="6.76099941307626" />
      <inertia
        ixx="0.0241007935216868"
        ixy="-4.07055219750389E-06"
        ixz="0.00052429441504994"
        iyy="0.0245027073583885"
        iyz="-0.000170307131198768"
        izz="0.0057717631268867" />
    </inertial>
    <visual>
      <origin
        xyz="0 0 0"
        rpy="0 0 0" />
      <geometry>
        <mesh
          filename="package://SIA_robot/meshes/link-R3.STL" />
      </geometry>
      <material
        name="">
        <color
          rgba="1 1 1 1" />
      </material>
    </visual>
    <collision>
      <origin
        xyz="0 0 0"
        rpy="0 0 0" />
      <geometry>
        <mesh
          filename="package://SIA_robot/meshes/link-R3.STL" />
      </geometry>
    </collision>
  </link>
  <joint
    name="R-J3"
    type="revolute">
    <origin
      xyz="0 -0.3 0"
      rpy="1.5708 0 0" />
    <parent
      link="link-R2" />
    <child
      link="link-R3" />
    <axis
      xyz="0 0 1" />
    <limit
      lower="-3.0543"
      upper="3.0543"
      effort="0"
      velocity="0" />
  </joint>
  <link
    name="link-R4">
    <inertial>
      <origin
        xyz="1.55020330738775E-06 -0.0327095870323233 -0.000281996819201039"
        rpy="0 0 0" />
      <mass
        value="6.86474413283516" />
      <inertia
        ixx="0.0198391962830934"
        ixy="-2.77202330132127E-07"
        ixz="-1.52336964149364E-08"
        iyy="0.00950734139914809"
        iyz="5.51814068233546E-05"
        izz="0.0163570915356325" />
    </inertial>
    <visual>
      <origin
        xyz="0 0 0"
        rpy="0 0 0" />
      <geometry>
        <mesh
          filename="package://SIA_robot/meshes/link-R4.STL" />
      </geometry>
      <material
        name="">
        <color
          rgba="1 1 1 1" />
      </material>
    </visual>
    <collision>
      <origin
        xyz="0 0 0"
        rpy="0 0 0" />
      <geometry>
        <mesh
          filename="package://SIA_robot/meshes/link-R4.STL" />
      </geometry>
    </collision>
  </link>
  <joint
    name="R-J4"
    type="revolute">
    <origin
      xyz="0 0 0"
      rpy="-1.5708 0 0" />
    <parent
      link="link-R3" />
    <child
      link="link-R4" />
    <axis
      xyz="0 0 1" />
    <limit
      lower="-2.3538"
      upper="1.7123"
      effort="0"
      velocity="0" />
  </joint>
  <link
    name="link-R5">
    <inertial>
      <origin
        xyz="2.61938777335047E-06 0.000664248517209837 -0.0552339020133823"
        rpy="0 0 0" />
      <mass
        value="3.13715935450461" />
      <inertia
        ixx="0.00617168729257163"
        ixy="9.57723919184407E-08"
        ixz="-4.53982816082471E-07"
        iyy="0.00650310856970505"
        iyz="-0.000114073990108045"
        izz="0.00207599235031165" />
    </inertial>
    <visual>
      <origin
        xyz="0 0 0"
        rpy="0 0 0" />
      <geometry>
        <mesh
          filename="package://SIA_robot/meshes/link-R5.STL" />
      </geometry>
      <material
        name="">
        <color
          rgba="1 1 1 1" />
      </material>
    </visual>
    <collision>
      <origin
        xyz="0 0 0"
        rpy="0 0 0" />
      <geometry>
        <mesh
          filename="package://SIA_robot/meshes/link-R5.STL" />
      </geometry>
    </collision>
  </link>
  <joint
    name="R-J5"
    type="revolute">
    <origin
      xyz="0 -0.22 0"
      rpy="1.5708 0 0" />
    <parent
      link="link-R4" />
    <child
      link="link-R5" />
    <axis
      xyz="0 0 1" />
    <limit
      lower="-3.0543"
      upper="3.0543"
      effort="0"
      velocity="0" />
  </joint>
  <link
    name="link-R6">
    <inertial>
      <origin
        xyz="1.46922276367256E-06 -0.0320401134442209 -0.000354045768412676"
        rpy="0 0 0" />
      <mass
        value="5.41190432381934" />
      <inertia
        ixx="0.0130568238032191"
        ixy="-2.44895572730431E-07"
        ixz="1.52953724925497E-07"
        iyy="0.00624175373758098"
        iyz="5.44179711474993E-05"
        izz="0.0110970473747011" />
    </inertial>
    <visual>
      <origin
        xyz="0 0 0"
        rpy="0 0 0" />
      <geometry>
        <mesh
          filename="package://SIA_robot/meshes/link-R6.STL" />
      </geometry>
      <material
        name="">
        <color
          rgba="0.776470588235294 0.756862745098039 0.737254901960784 1" />
      </material>
    </visual>
    <collision>
      <origin
        xyz="0 0 0"
        rpy="0 0 0" />
      <geometry>
        <mesh
          filename="package://SIA_robot/meshes/link-R6.STL" />
      </geometry>
    </collision>
  </link>
  <joint
    name="R-J6"
    type="revolute">
    <origin
      xyz="0 0 0"
      rpy="-1.5708 0 0" />
    <parent
      link="link-R5" />
    <child
      link="link-R6" />
    <axis
      xyz="0 0 1" />
    <limit
      lower="-2.0944"
      upper="2.0944"
      effort="0"
      velocity="0" />
  </joint>
  <link
    name="link-R7">
    <inertial>
      <origin
        xyz="0.000201227208657229 -4.45951571791945E-06 -0.0324015634635619"
        rpy="0 0 0" />
      <mass
        value="2.17471093562456" />
      <inertia
        ixx="0.00140827770383968"
        ixy="-4.53525874180243E-09"
        ixz="-1.01773030744789E-05"
        iyy="0.00142257226784241"
        iyz="-2.4533932555503E-07"
        izz="0.00166147868684454" />
    </inertial>
    <visual>
      <origin
        xyz="0 0 0"
        rpy="0 0 0" />
      <geometry>
        <mesh
          filename="package://SIA_robot/meshes/link-R7.STL" />
      </geometry>
      <material
        name="">
        <color
          rgba="0.776470588235294 0.756862745098039 0.737254901960784 1" />
      </material>
    </visual>
    <collision>
      <origin
        xyz="0 0 0"
        rpy="0 0 0" />
      <geometry>
        <mesh
          filename="package://SIA_robot/meshes/link-R7.STL" />
      </geometry>
    </collision>
  </link>
  <joint
    name="R-J7"
    type="revolute">
    <origin
      xyz="0 -0.164 0"
      rpy="1.5708 0 0" />
    <parent
      link="link-R6" />
    <child
      link="link-R7" />
    <axis
      xyz="0 0 1" />
    <limit
      lower="-3.0543"
      upper="3.0543"
      effort="0"
      velocity="0" />
  </joint>
  <link
    name="link-Rtool">
    <inertial>
      <origin
        xyz="0.000108228106315056 -1.58700641768567E-05 -0.033217114965277"
        rpy="0 0 0" />
      <mass
        value="0.2339522890314" />
      <inertia
        ixx="0.000108307997361677"
        ixy="5.76555958161368E-08"
        ixz="-9.61151743846956E-08"
        iyy="0.000110720195394877"
        iyz="-8.59971960181788E-09"
        izz="0.000197661960567637" />
    </inertial>
    <visual>
      <origin
        xyz="0 0 0"
        rpy="0 0 0" />
      <geometry>
        <mesh
          filename="package://SIA_robot/meshes/link-Rtool.STL" />
      </geometry>
      <material
        name="">
        <color
          rgba="0.792156862745098 0.819607843137255 0.933333333333333 1" />
      </material>
    </visual>
    <collision>
      <origin
        xyz="0 0 0"
        rpy="0 0 0" />
      <geometry>
        <mesh
          filename="package://SIA_robot/meshes/link-Rtool.STL" />
      </geometry>
    </collision>
  </link>
  <joint
    name="R-tool"
    type="fixed">
    <origin
      xyz="0 0 0.072399"
      rpy="0 0 0" />
    <parent
      link="link-R7" />
    <child
      link="link-Rtool" />
    <axis
      xyz="0 0 0" />
  </joint>
  <link
    name="link-L0">
    <inertial>
      <origin
        xyz="1.6666483512664E-05 0.000428575028515121 0.0387665520212093"
        rpy="0 0 0" />
      <mass
        value="4.48243687136841" />
      <inertia
        ixx="0.00516757527508331"
        ixy="-6.99003877942928E-07"
        ixz="1.89822417332268E-06"
        iyy="0.00522193992152107"
        iyz="4.8218371298447E-05"
        izz="0.00566118382384421" />
    </inertial>
    <visual>
      <origin
        xyz="0 0 0"
        rpy="0 0 0" />
      <geometry>
        <mesh
          filename="package://SIA_robot/meshes/link-L0.STL" />
      </geometry>
      <material
        name="">
        <color
          rgba="1 1 1 1" />
      </material>
    </visual>
    <collision>
      <origin
        xyz="0 0 0"
        rpy="0 0 0" />
      <geometry>
        <mesh
          filename="package://SIA_robot/meshes/link-L0.STL" />
      </geometry>
    </collision>
  </link>
  <joint
    name="L-J0"
    type="fixed">
    <origin
      xyz="0 0.09 -0.075"
      rpy="-1.5708 0 0" />
    <parent
      link="Link-Body" />
    <child
      link="link-L0" />
    <axis
      xyz="0 0 0" />
  </joint>
  <link
    name="link-L1">
    <inertial>
      <origin
        xyz="3.21247853196649E-06 -0.000524470579303317 -0.0441242557403994"
        rpy="0 0 0" />
      <mass
        value="3.29940267206884" />
      <inertia
        ixx="0.00538963812553377"
        ixy="-3.4095024805657E-09"
        ixz="4.5452558593587E-07"
        iyy="0.00597561361790467"
        iyz="7.6416224176846E-05"
        izz="0.00258712975381606" />
    </inertial>
    <visual>
      <origin
        xyz="0 0 0"
        rpy="0 0 0" />
      <geometry>
        <mesh
          filename="package://SIA_robot/meshes/link-L1.STL" />
      </geometry>
      <material
        name="">
        <color
          rgba="1 1 1 1" />
      </material>
    </visual>
    <collision>
      <origin
        xyz="0 0 0"
        rpy="0 0 0" />
      <geometry>
        <mesh
          filename="package://SIA_robot/meshes/link-L1.STL" />
      </geometry>
    </collision>
  </link>
  <joint
    name="L-J1"
    type="revolute">
    <origin
      xyz="0 0 0.172"
      rpy="0 0 1.5708" />
    <parent
      link="link-L0" />
    <child
      link="link-L1" />
    <axis
      xyz="0 0 1" />
    <limit
      lower="-3.0543"
      upper="3.0543"
      effort="0"
      velocity="0" />
  </joint>
  <link
    name="link-L2">
    <inertial>
      <origin
        xyz="1.21053463830734E-06 -0.0553985275990222 0.00166564644389522"
        rpy="0 0 0" />
      <mass
        value="5.63523249981779" />
      <inertia
        ixx="0.0152384532072431"
        ixy="1.14857930990107E-06"
        ixz="-2.69260236187485E-08"
        iyy="0.00674678405526804"
        iyz="-0.000400962800547985"
        izz="0.0142810952659943" />
    </inertial>
    <visual>
      <origin
        xyz="0 0 0"
        rpy="0 0 0" />
      <geometry>
        <mesh
          filename="package://SIA_robot/meshes/link-L2.STL" />
      </geometry>
      <material
        name="">
        <color
          rgba="0.776470588235294 0.756862745098039 0.737254901960784 1" />
      </material>
    </visual>
    <collision>
      <origin
        xyz="0 0 0"
        rpy="0 0 0" />
      <geometry>
        <mesh
          filename="package://SIA_robot/meshes/link-L2.STL" />
      </geometry>
    </collision>
  </link>
  <joint
    name="L-J2"
    type="revolute">
    <origin
      xyz="0 0 0"
      rpy="-1.5708 0 0" />
    <parent
      link="link-L1" />
    <child
      link="link-L2" />
    <axis
      xyz="0 0 1" />
    <limit
      lower="-1.8246"
      upper="1.8246"
      effort="0"
      velocity="0" />
  </joint>
  <link
    name="link-L3">
    <inertial>
      <origin
        xyz="-0.00237096053014541 -0.000255872829113588 -0.0989215541692502"
        rpy="0 0 0" />
      <mass
        value="6.76099916761065" />
      <inertia
        ixx="0.024100801563671"
        ixy="4.13004276507571E-06"
        ixz="0.000525412389026435"
        iyy="0.0245026519037375"
        iyz="0.000172055474478548"
        izz="0.00577171893802094" />
    </inertial>
    <visual>
      <origin
        xyz="0 0 0"
        rpy="0 0 0" />
      <geometry>
        <mesh
          filename="package://SIA_robot/meshes/link-L3.STL" />
      </geometry>
      <material
        name="">
        <color
          rgba="1 1 1 1" />
      </material>
    </visual>
    <collision>
      <origin
        xyz="0 0 0"
        rpy="0 0 0" />
      <geometry>
        <mesh
          filename="package://SIA_robot/meshes/link-L3.STL" />
      </geometry>
    </collision>
  </link>
  <joint
    name="L-J3"
    type="revolute">
    <origin
      xyz="0 -0.3 0"
      rpy="1.5708 0 0" />
    <parent
      link="link-L2" />
    <child
      link="link-L3" />
    <axis
      xyz="0 0 1" />
    <limit
      lower="-3.0543"
      upper="3.0543"
      effort="0"
      velocity="0" />
  </joint>
  <link
    name="link-L4">
    <inertial>
      <origin
        xyz="-1.55086507591662E-06 -0.03270958685873 0.000281998045914173"
        rpy="0 0 0" />
      <mass
        value="6.86474389336079" />
      <inertia
        ixx="0.0198391959633156"
        ixy="2.7718149887142E-07"
        ixz="-1.54048707117146E-08"
        iyy="0.00950734101323493"
        iyz="-5.51813656186912E-05"
        izz="0.0163570914575466" />
    </inertial>
    <visual>
      <origin
        xyz="0 0 0"
        rpy="0 0 0" />
      <geometry>
        <mesh
          filename="package://SIA_robot/meshes/link-L4.STL" />
      </geometry>
      <material
        name="">
        <color
          rgba="1 1 1 1" />
      </material>
    </visual>
    <collision>
      <origin
        xyz="0 0 0"
        rpy="0 0 0" />
      <geometry>
        <mesh
          filename="package://SIA_robot/meshes/link-L4.STL" />
      </geometry>
    </collision>
  </link>
  <joint
    name="L-J4"
    type="revolute">
    <origin
      xyz="0 0 0"
      rpy="-1.5708 0 0" />
    <parent
      link="link-L3" />
    <child
      link="link-L4" />
    <axis
      xyz="0 0 1" />
    <limit
      lower="-2.3538"
      upper="1.7123"
      effort="0"
      velocity="0" />
  </joint>
  <link
    name="link-L5">
    <inertial>
      <origin
        xyz="-2.61938705747866E-06 -0.000664248517338731 -0.055233902013257"
        rpy="0 0 0" />
      <mass
        value="3.13715935446969" />
      <inertia
        ixx="0.00617168729256577"
        ixy="9.57723801003195E-08"
        ixz="4.53982841712059E-07"
        iyy="0.00650310856968162"
        iyz="0.000114073990132104"
        izz="0.0020759923502868" />
    </inertial>
    <visual>
      <origin
        xyz="0 0 0"
        rpy="0 0 0" />
      <geometry>
        <mesh
          filename="package://SIA_robot/meshes/link-L5.STL" />
      </geometry>
      <material
        name="">
        <color
          rgba="1 1 1 1" />
      </material>
    </visual>
    <collision>
      <origin
        xyz="0 0 0"
        rpy="0 0 0" />
      <geometry>
        <mesh
          filename="package://SIA_robot/meshes/link-L5.STL" />
      </geometry>
    </collision>
  </link>
  <joint
    name="L-J5"
    type="revolute">
    <origin
      xyz="0 -0.22 0"
      rpy="1.5708 0 0" />
    <parent
      link="link-L4" />
    <child
      link="link-L5" />
    <axis
      xyz="0 0 1" />
    <limit
      lower="-3.0543"
      upper="3.0543"
      effort="0"
      velocity="0" />
  </joint>
  <link
    name="link-L6">
    <inertial>
      <origin
        xyz="-1.46922276367256E-06 -0.0320401134442212 0.000354045767970296"
        rpy="0 0 0" />
      <mass
        value="5.41190432381933" />
      <inertia
        ixx="0.0130568238032191"
        ixy="2.4489557274105E-07"
        ixz="1.5295372493794E-07"
        iyy="0.00624175373758096"
        iyz="-5.44179711474942E-05"
        izz="0.0110970473747011" />
    </inertial>
    <visual>
      <origin
        xyz="0 0 0"
        rpy="0 0 0" />
      <geometry>
        <mesh
          filename="package://SIA_robot/meshes/link-L6.STL" />
      </geometry>
      <material
        name="">
        <color
          rgba="0.776470588235294 0.756862745098039 0.737254901960784 1" />
      </material>
    </visual>
    <collision>
      <origin
        xyz="0 0 0"
        rpy="0 0 0" />
      <geometry>
        <mesh
          filename="package://SIA_robot/meshes/link-L6.STL" />
      </geometry>
    </collision>
  </link>
  <joint
    name="L-J6"
    type="revolute">
    <origin
      xyz="0 0 0"
      rpy="-1.5708 0 0" />
    <parent
      link="link-L5" />
    <child
      link="link-L6" />
    <axis
      xyz="0 0 1" />
    <limit
      lower="-2.0944"
      upper="2.0944"
      effort="0"
      velocity="0" />
  </joint>
  <link
    name="link-L7">
    <inertial>
      <origin
        xyz="0.000201227208658783 -4.45951226892605E-06 -0.0324015634635619"
        rpy="0 0 0" />
      <mass
        value="2.17471093562457" />
      <inertia
        ixx="0.00140827770383969"
        ixy="-4.53525875977876E-09"
        ixz="-1.01773030744803E-05"
        iyy="0.00142257226784241"
        iyz="-2.4533932510959E-07"
        izz="0.00166147868684455" />
    </inertial>
    <visual>
      <origin
        xyz="0 0 0"
        rpy="0 0 0" />
      <geometry>
        <mesh
          filename="package://SIA_robot/meshes/link-L7.STL" />
      </geometry>
      <material
        name="">
        <color
          rgba="0.776470588235294 0.756862745098039 0.737254901960784 1" />
      </material>
    </visual>
    <collision>
      <origin
        xyz="0 0 0"
        rpy="0 0 0" />
      <geometry>
        <mesh
          filename="package://SIA_robot/meshes/link-L7.STL" />
      </geometry>
    </collision>
  </link>
  <joint
    name="L-J7"
    type="revolute">
    <origin
      xyz="0 -0.164 0"
      rpy="1.5708 0 0" />
    <parent
      link="link-L6" />
    <child
      link="link-L7" />
    <axis
      xyz="0 0 1" />
    <limit
      lower="-3.0543"
      upper="3.0543"
      effort="0"
      velocity="0" />
  </joint>
  <link
    name="link-Ltool">
    <inertial>
      <origin
        xyz="0.000109753641508337 -1.6093767850178E-05 -0.0269481337256603"
        rpy="0 0 0" />
      <mass
        value="0.230700440407675" />
      <inertia
        ixx="0.000104208489619373"
        ixy="5.76643215390902E-08"
        ixz="-6.47742951675152E-08"
        iyy="0.000106620567904689"
        iyz="-3.13502539431154E-09"
        izz="0.000192988356501623" />
    </inertial>
    <visual>
      <origin
        xyz="0 0 0"
        rpy="0 0 0" />
      <geometry>
        <mesh
          filename="package://SIA_robot/meshes/link-Ltool.STL" />
      </geometry>
      <material
        name="">
        <color
          rgba="0.792156862745098 0.819607843137255 0.933333333333333 1" />
      </material>
    </visual>
    <collision>
      <origin
        xyz="0 0 0"
        rpy="0 0 0" />
      <geometry>
        <mesh
          filename="package://SIA_robot/meshes/link-Ltool.STL" />
      </geometry>
    </collision>
  </link>
  <joint
    name="L-tool"
    type="fixed">
    <origin
      xyz="0 0 0.064399"
      rpy="0 0 0" />
    <parent
      link="link-L7" />
    <child
      link="link-Ltool" />
    <axis
      xyz="0 0 0" />
  </joint>
  <link
    name="link-H1">
    <inertial>
      <origin
        xyz="0.00143601240487204 0.00399729515756818 -0.0130277192812951"
        rpy="0 0 0" />
      <mass
        value="0.0972089924761052" />
      <inertia
        ixx="2.39224248667145E-05"
        ixy="-1.46844515801986E-07"
        ixz="-2.53729271028935E-06"
        iyy="3.68919711015593E-05"
        iyz="-1.36177837798517E-07"
        izz="3.47334776195984E-05" />
    </inertial>
    <visual>
      <origin
        xyz="0 0 0"
        rpy="0 0 0" />
      <geometry>
        <mesh
          filename="package://SIA_robot/meshes/link-H1.STL" />
      </geometry>
      <material
        name="">
        <color
          rgba="0.792156862745098 0.819607843137255 0.933333333333333 1" />
      </material>
    </visual>
    <collision>
      <origin
        xyz="0 0 0"
        rpy="0 0 0" />
      <geometry>
        <mesh
          filename="package://SIA_robot/meshes/link-H1.STL" />
      </geometry>
    </collision>
  </link>
  <joint
    name="H-J1"
    type="revolute">
    <origin
      xyz="0 0 0.06655"
      rpy="0 0 0" />
    <parent
      link="Link-Body" />
    <child
      link="link-H1" />
    <axis
      xyz="0 0 1" />
    <limit
      lower="-3.14"
      upper="3.14"
      effort="0"
      velocity="0" />
  </joint>
  <link
    name="link-H2">
    <inertial>
      <origin
        xyz="0.0207949033546781 -0.0845619965913866 0.000741712456379605"
        rpy="0 0 0" />
      <mass
        value="0.370390486643493" />
      <inertia
        ixx="0.00194303023381918"
        ixy="-0.000181411351354721"
        ixz="1.91808717006784E-06"
        iyy="0.00152247523425536"
        iyz="8.46665148980836E-07"
        izz="0.000842200739248113" />
    </inertial>
    <visual>
      <origin
        xyz="0 0 0"
        rpy="0 0 0" />
      <geometry>
        <mesh
          filename="package://SIA_robot/meshes/link-H2.STL" />
      </geometry>
      <material
        name="">
        <color
          rgba="0.792156862745098 0.819607843137255 0.933333333333333 1" />
      </material>
    </visual>
    <collision>
      <origin
        xyz="0 0 0"
        rpy="0 0 0" />
      <geometry>
        <mesh
          filename="package://SIA_robot/meshes/link-H2.STL" />
      </geometry>
    </collision>
  </link>
  <joint
    name="H-J2"
    type="revolute">
    <origin
      xyz="0 0 0"
      rpy="-1.5708 0 0" />
    <parent
      link="link-H1" />
    <child
      link="link-H2" />
    <axis
      xyz="0 0 1" />
    <limit
      lower="-1.5708"
      upper="1.5708"
      effort="0"
      velocity="0" />
  </joint>
  <link
    name="link-realsense">
    <inertial>
      <origin
        xyz="0.0322543986624866 6.03314827074541E-05 -0.0125498678920444"
        rpy="0 0 0" />
      <mass
        value="0.0447467360808164" />
      <inertia
        ixx="3.94486330723015E-06"
        ixy="-3.10310055909044E-09"
        ixz="-2.44513034413358E-07"
        iyy="2.73626295208831E-05"
        iyz="1.09640575825865E-09"
        izz="2.72781186721372E-05" />
    </inertial>
    <visual>
      <origin
        xyz="0 0 0"
        rpy="0 0 0" />
      <geometry>
        <mesh
          filename="package://SIA_robot/meshes/link-realsense.STL" />
      </geometry>
      <material
        name="">
        <color
          rgba="0.792156862745098 0.819607843137255 0.933333333333333 1" />
      </material>
    </visual>
    <collision>
      <origin
        xyz="0 0 0"
        rpy="0 0 0" />
      <geometry>
        <mesh
          filename="package://SIA_robot/meshes/link-realsense.STL" />
      </geometry>
    </collision>
  </link>
  <joint
    name="J-realsense"
    type="fixed">
    <origin
      xyz="0.07 -0.1305 0.032498"
      rpy="0 1.5708 0" />
    <parent
      link="link-H2" />
    <child
      link="link-realsense" />
    <axis
      xyz="0 0 0" />
  </joint>
  <link
    name="link-zed">
    <inertial>
      <origin
        xyz="0.0599972918175352 -6.22579607822971E-06 -0.0161109295588259"
        rpy="0 0 0" />
      <mass
        value="0.152411602303506" />
      <inertia
        ixx="2.28615403166201E-05"
        ixy="6.23540444474161E-09"
        ixz="2.39714520739596E-09"
        iyy="0.000374755631371841"
        iyz="-2.07865484370704E-08"
        izz="0.000372358627433334" />
    </inertial>
    <visual>
      <origin
        xyz="0 0 0"
        rpy="0 0 0" />
      <geometry>
        <mesh
          filename="package://SIA_robot/meshes/link-zed.STL" />
      </geometry>
      <material
        name="">
        <color
          rgba="0.411764705882353 0.411764705882353 0.411764705882353 1" />
      </material>
    </visual>
    <collision>
      <origin
        xyz="0 0 0"
        rpy="0 0 0" />
      <geometry>
        <mesh
          filename="package://SIA_robot/meshes/link-zed.STL" />
      </geometry>
    </collision>
  </link>
  <joint
    name="J-zed"
    type="fixed">
    <origin
      xyz="0.068259 -0.091783 0.059998"
      rpy="0 1.5708 0" />
    <parent
      link="link-H2" />
    <child
      link="link-zed" />
    <axis
      xyz="0 0 0" />
  </joint>
</robot>