<?xml version="1.0" encoding="utf-8"?>
<!-- This URDF was automatically created by SolidWorks to URDF Exporter! Originally created by Stephen Brawner (brawner@gmail.com) 
     Commit Version: 1.5.1-0-g916b5db  Build Version: 1.5.7152.31018
     For more information, please see http://wiki.ros.org/sw_urdf_exporter -->
<robot name="xmate_robot" xmlns:xacro="http://ros.org/wiki/xacro">
  <xacro:property name = "pkg_address" value = "file://$(find xmate_description)"/>
  <link name="base_footprint">
      <visual>
          <origin xyz="0 0 0" rpy="0 0 0" />
          <geometry>
              <box size="0.001 0.001 0.001" />
          </geometry>
      </visual>
  </link>

  <joint name="base_footprint_joint" type="fixed">
      <origin xyz="0 0 0.001" rpy="0 0 0" />
      <parent link="base_footprint"/>
      <child link="base_link" />
  </joint>
  <link
    name="base_link">
    <inertial>
      <origin
        xyz="-0.0190878642878959 4.44287082767532E-05 0.0624104395985687"
        rpy="0 0 0" />
      <mass
        value="3.14882981307727" />
      <inertia
        ixx="0.011844482554324"
        ixy="2.92405347400916E-05"
        ixz="-0.00194355041177005"
        iyy="0.0164852496556854"
        iyz="5.29659484045488E-06"
        izz="0.0135747664674373" />
    </inertial>
    <visual>
      <origin
        xyz="0 0 0"
        rpy="0 0 0" />
      <geometry>
        <mesh
          filename="${pkg_address}/meshes/visual/base_link.STL" />
      </geometry>
      <material
        name="">
        <color
          rgba="0.792156862745098 0.819607843137255 0.933333333333333 1" />
      </material>
    </visual>
    <collision>
      <origin
        xyz="0 0 0"
        rpy="0 0 0" />
      <geometry>
        <mesh
          filename="${pkg_address}/meshes/visual/base_link.STL" />
      </geometry>
    </collision>
  </link>
  <link
    name="link1">
    <inertial>
      <origin
        xyz="3.75776496543655E-06 -0.0252734418675507 -0.0534436826389869"
        rpy="0 0 0" />
      <mass
        value="1.80046930093093" />
      <inertia
        ixx="0.00956980817827696"
        ixy="-6.86187842720972E-07"
        ixz="-4.77939852843324E-07"
        iyy="0.00856427639632967"
        iyz="0.0019572725590109"
        izz="0.00330558169450564" />
    </inertial>
    <visual>
      <origin
        xyz="0 0 0"
        rpy="0 0 0" />
      <geometry>
        <mesh
          filename="${pkg_address}/meshes/visual/link1.STL" />
      </geometry>
      <material
        name="">
        <color
          rgba="0.792156862745098 0.819607843137255 0.933333333333333 1" />
      </material>
    </visual>
    <collision>
      <origin
        xyz="0 0 0"
        rpy="0 0 0" />
      <geometry>
        <mesh
          filename="${pkg_address}/meshes/visual/link1.STL" />
      </geometry>
    </collision>
  </link>
  <joint
    name="joint1"
    type="revolute">
    <origin
      xyz="0 0 0.3415"
      rpy="0 0 0" />
    <parent
      link="base_link" />
    <child
      link="link1" />
    <axis
      xyz="0 0 1" />
    <limit
      lower="-2.9671"
      upper="2.9671"
      effort="85"
      velocity="0" />
  </joint>
  <link
    name="link2">
    <inertial>
      <origin
        xyz="-5.90818631893836E-06 -0.0946880344410013 0.0276358977076862"
        rpy="0 0 0" />
      <mass
        value="2.18528055019099" />
      <inertia
        ixx="0.0179611048384866"
        ixy="2.15053083139611E-07"
        ixz="7.21438492051777E-07"
        iyy="0.00446729731923892"
        iyz="-0.00456714437433753"
        izz="0.0162948270439588" />
    </inertial>
    <visual>
      <origin
        xyz="0 0 0"
        rpy="0 0 0" />
      <geometry>
        <mesh
          filename="${pkg_address}/meshes/visual/link2.STL" />
      </geometry>
      <material
        name="">
        <color
          rgba="0.792156862745098 0.819607843137255 0.933333333333333 1" />
      </material>
    </visual>
    <collision>
      <origin
        xyz="0 0 0"
        rpy="0 0 0" />
      <geometry>
        <mesh
          filename="${pkg_address}/meshes/visual/link2.STL" />
      </geometry>
    </collision>
  </link>
  <joint
    name="joint2"
    type="revolute">
    <origin
      xyz="0 0 0"
      rpy="-1.5708 0 0" />
    <parent
      link="link1" />
    <child
      link="link2" />
    <axis
      xyz="0 0 1" />
    <limit
      lower="-2.0944"
      upper="2.0944"
      effort="85"
      velocity="0" />
  </joint>
  <link
    name="link3">
    <inertial>
      <origin
        xyz="2.16568816054606E-06 -0.0250285877752692 -0.0536194526280217"
        rpy="0 0 0" />
      <mass
        value="1.79439914744383" />
      <inertia
        ixx="0.00952181106006989"
        ixy="-6.22714495423591E-07"
        ixz="-6.1128894084889E-07"
        iyy="0.0085458141551332"
        iyz="0.00193686439373285"
        izz="0.0032759628481035" />
    </inertial>
    <visual>
      <origin
        xyz="0 0 0"
        rpy="0 0 0" />
      <geometry>
        <mesh
          filename="${pkg_address}/meshes/visual/link3.STL" />
      </geometry>
      <material
        name="">
        <color
          rgba="0.792156862745098 0.819607843137255 0.933333333333333 1" />
      </material>
    </visual>
    <collision>
      <origin
        xyz="0 0 0"
        rpy="0 0 0" />
      <geometry>
        <mesh
          filename="${pkg_address}/meshes/visual/link3.STL" />
      </geometry>
    </collision>
  </link>
  <joint
    name="joint3"
    type="revolute">
    <origin
      xyz="0 -0.394 0"
      rpy="1.5708 0 0" />
    <parent
      link="link2" />
    <child
      link="link3" />
    <axis
      xyz="0 0 1" />
    <limit
      lower="-2.9671"
      upper="2.9671"
      effort="85"
      velocity="0" />
  </joint>
  <link
    name="link4">
    <inertial>
      <origin
        xyz="2.21985855306493E-06 -0.0758073970252477 0.0327811721602507"
        rpy="0 0 0" />
      <mass
        value="1.79656819645689" />
      <inertia
        ixx="0.0130624358389442"
        ixy="7.3310655032143E-07"
        ixz="1.57222677694707E-07"
        iyy="0.00334822720012112"
        iyz="-0.0034596075696428"
        izz="0.0117335196362426" />
    </inertial>
    <visual>
      <origin
        xyz="0 0 0"
        rpy="0 0 0" />
      <geometry>
        <mesh
          filename="${pkg_address}/meshes/visual/link4.STL" />
      </geometry>
      <material
        name="">
        <color
          rgba="0.792156862745098 0.819607843137255 0.933333333333333 1" />
      </material>
    </visual>
    <collision>
      <origin
        xyz="0 0 0"
        rpy="0 0 0" />
      <geometry>
        <mesh
          filename="${pkg_address}/meshes/visual/link4.STL" />
      </geometry>
    </collision>
  </link>
  <joint
    name="joint4"
    type="revolute">
    <origin
      xyz="0 0 0"
      rpy="-1.5708 0 0" />
    <parent
      link="link3" />
    <child
      link="link4" />
    <axis
      xyz="0 0 1" />
    <limit
      lower="-2.0944"
      upper="2.0944"
      effort="85"
      velocity="0" />
  </joint>
  <link
    name="link5">
    <inertial>
      <origin
        xyz="1.21981613279802E-05 -0.0312760212738299 -0.0457007273791392"
        rpy="0 0 0" />
      <mass
        value="1.29582025094736" />
      <inertia
        ixx="0.00598554443133607"
        ixy="-4.79416720212432E-07"
        ixz="5.48955442157535E-07"
        iyy="0.00489834395926307"
        iyz="0.00152656942938204"
        izz="0.00226750920938523" />
    </inertial>
    <visual>
      <origin
        xyz="0 0 0"
        rpy="0 0 0" />
      <geometry>
        <mesh
          filename="${pkg_address}/meshes/visual/link5.STL" />
      </geometry>
      <material
        name="">
        <color
          rgba="0.792156862745098 0.819607843137255 0.933333333333333 1" />
      </material>
    </visual>
    <collision>
      <origin
        xyz="0 0 0"
        rpy="0 0 0" />
      <geometry>
        <mesh
          filename="${pkg_address}/meshes/visual/link5.STL" />
      </geometry>
    </collision>
  </link>
  <joint
    name="joint5"
    type="revolute">
    <origin
      xyz="0 -0.366 0"
      rpy="1.5708 0 0" />
    <parent
      link="link4" />
    <child
      link="link5" />
    <axis
      xyz="0 0 1" />
    <limit
      lower="-2.9671"
      upper="2.9671"
      effort="36"
      velocity="0" />
  </joint>
  <link
    name="link6">
    <inertial>
      <origin
        xyz="1.20427803352186E-05 -0.0842935496420196 0.0150293848832451"
        rpy="0 0 0" />
      <mass
        value="1.22517411641495" />
      <inertia
        ixx="0.00628411319377034"
        ixy="-3.44725394857607E-07"
        ixz="-1.0526663359284E-07"
        iyy="0.00146492901184975"
        iyz="-0.00128418728953825"
        izz="0.0059858090558361" />
    </inertial>
    <visual>
      <origin
        xyz="0 0 0"
        rpy="0 0 0" />
      <geometry>
        <mesh
          filename="${pkg_address}/meshes/visual/link6.STL" />
      </geometry>
      <material
        name="">
        <color
          rgba="0.792156862745098 0.819607843137255 0.933333333333333 1" />
      </material>
    </visual>
    <collision>
      <origin
        xyz="0 0 0"
        rpy="0 0 0" />
      <geometry>
        <mesh
          filename="${pkg_address}/meshes/visual/link6.STL" />
      </geometry>
    </collision>
  </link>
  <joint
    name="joint6"
    type="revolute">
    <origin
      xyz="0 0 0"
      rpy="-1.5708 0 0" />
    <parent
      link="link5" />
    <child
      link="link6" />
    <axis
      xyz="0 0 1" />
    <limit
      lower="-2.0944"
      upper="2.0944"
      effort="36"
      velocity="0" />
  </joint>
  <link
    name="link7">
    <inertial>
      <origin
        xyz="4.73025266461632E-05 0.0229430859199964 -0.0447568407189354"
        rpy="0 0 0" />
      <mass
        value="0.542741113197497" />
      <inertia
        ixx="0.00116639457832694"
        ixy="-2.22236937889454E-07"
        ixz="-4.20922257638247E-07"
        iyy="0.000638418120517027"
        iyz="0.00028236152146618"
        izz="0.000951964055085044" />
    </inertial>
    <visual>
      <origin
        xyz="0 0 0"
        rpy="0 0 0" />
      <geometry>
        <mesh
          filename="${pkg_address}/meshes/visual/link7.STL" />
      </geometry>
      <material
        name="">
        <color
          rgba="0.792156862745098 0.819607843137255 0.933333333333333 1" />
      </material>
    </visual>
    <collision>
      <origin
        xyz="0 0 0"
        rpy="0 0 0" />
      <geometry>
        <mesh
          filename="${pkg_address}/meshes/visual/link7.STL" />
      </geometry>
    </collision>
  </link>
  <joint
    name="joint7"
    type="revolute">
    <origin
      xyz="0 -0.2503 0"
      rpy="1.5708 0 0" />
    <parent
      link="link6" />
    <child
      link="link7" />
    <axis
      xyz="0 0 1" />
    <limit
      lower="-3.14"
      upper="3.14"
      effort="36"
      velocity="0" />
  </joint>
  
</robot>


